<?xml version="1.0" ?>
<!-- =================================================================================== -->
<!-- |    This document was autogenerated by xacro from /root/uav_ws/src/aerial_manipulators/aerial_manipulators_description/urdf/wp_manipulator_moveit.base.urdf.xacro | -->
<!-- |    EDITING THIS FILE BY HAND IS NOT RECOMMENDED                                 | -->
<!-- =================================================================================== -->
<robot name="wp_manipulator">
    <link name="world" />
    <link name="base">
        <inertial>
            <mass value="0.009947252747252746" />
            <origin rpy="0 0 0" xyz="0 -0.02263 0" />
            <inertia ixx="4.476263736263735e-06" ixy="0" ixz="0" iyx="0" iyy="3.936183948278388e-06" iyz="0" izx="0" izy="0" izz="3.936183948278388e-06" />
        </inertial>
        <visual>
            <origin rpy="0 0 0" xyz="0 0 0" />
            <geometry>
                <mesh filename="package://aerial_manipulators_description/meshes/wp_manipulator/base.dae" scale="1 1 1" />
            </geometry>
        </visual>
    </link>
    <link name="link1">
        <inertial>
            <mass value="0.026920879120879117" />
            <origin rpy="0 0 0" xyz="0 0.061245 0" />
            <inertia ixx="3.9716821872692296e-05" ixy="0" ixz="0" iyx="0" iyy="1.2114395604395603e-05" iyz="0" izx="0" izy="0" izz="3.9716821872692296e-05" />
        </inertial>
        <visual>
            <origin rpy="0 0 0" xyz="0 0 0" />
            <geometry>
                <mesh filename="package://aerial_manipulators_description/meshes/wp_manipulator/link1.dae" scale="1 1 1" />
            </geometry>
        </visual>
    </link>
    <link name="link2">
        <inertial>
            <mass value="0.03" />
            <origin rpy="0 0 0" xyz="0.06825 0 0" />
            <inertia ixx="1.35e-05" ixy="0" ixz="0" iyx="0" iyy="5.3330625e-05" iyz="0" izx="0" izy="0" izz="5.3330625e-05" />
        </inertial>
        <visual>
            <origin rpy="0 0 -1.5707963267948966" xyz="0 0 0" />
            <geometry>
                <mesh filename="package://aerial_manipulators_description/meshes/wp_manipulator/link2.dae" scale="1 1 1" />
            </geometry>
        </visual>
    </link>
    <link name="link3">
        <inertial>
            <mass value="0.016595824175824173" />
            <origin rpy="0 0 0" xyz="0.0377555 0 0" />
            <inertia ixx="7.468120879120877e-06" ixy="0" ixz="0" iyx="0" iyy="1.1619719975418148e-05" iyz="0" izx="0" izy="0" izz="1.1619719975418148e-05" />
        </inertial>
        <visual>
            <origin rpy="0 1.5707963267948966 -1.5707963267948966" xyz="0 0 0" />
            <geometry>
                <mesh filename="package://aerial_manipulators_description/meshes/wp_manipulator/link3.dae" scale="1 1 1" />
            </geometry>
        </visual>
    </link>
    <link name="link4">
        <inertial>
            <mass value="0.01593164835164835" />
            <origin rpy="0 0 0" xyz="0.0362445 0 0" />
            <inertia ixx="7.169241758241757e-06" ixy="0" ixz="0" iyx="0" iyy="1.0560897345534229e-05" iyz="0" izx="0" izy="0" izz="1.0560897345534229e-05" />
        </inertial>
        <visual>
            <origin rpy="0 1.5707963267948966 -1.5707963267948966" xyz="0 0 0" />
            <geometry>
                <mesh filename="package://aerial_manipulators_description/meshes/wp_manipulator/link4.dae" scale="1 1 1" />
            </geometry>
        </visual>
    </link>
    <link name="link5">
        <inertial>
            <mass value="0.009947252747252746" />
            <origin rpy="0 0 0" xyz="0.02263 0 0" />
            <inertia ixx="4.476263736263735e-06" ixy="0" ixz="0" iyx="0" iyy="3.936183948278388e-06" iyz="0" izx="0" izy="0" izz="3.936183948278388e-06" />
        </inertial>
        <visual>
            <origin rpy="0 1.5707963267948966 0" xyz="0 0 0" />
            <geometry>
                <mesh filename="package://aerial_manipulators_description/meshes/wp_manipulator/link5.dae" scale="1 1 1" />
            </geometry>
        </visual>
    </link>
    <link name="end_effector_base">
        <inertial>
            <mass value="0.00001" />
            <origin rpy="0 0 0" xyz="0 0 0" />
            <inertia ixx="0.00001" ixy="0" ixz="0" iyx="0" iyy="0.00001" iyz="0" izx="0" izy="0" izz="0.00001" />
        </inertial>
        <visual>
            <geometry>
                <sphere radius="0.005" />
            </geometry>
        </visual>
    </link>
    <joint name="wp_base_joint" type="fixed">
        <parent link="world" />
        <child link="base" />
        <origin rpy="0 0 0" xyz="0 0 0" />
    </joint>
    <joint name="joint1" type="revolute">
        <parent link="base" />
        <child link="link1" />
        <!-- Adjust Gazebo coordinate system to link1 coordinate system -->
        <origin rpy="0 0 0" xyz="0 0 0" />
        <limit effort="10000000" lower="-1.57" upper="1.57" velocity="46" />
        <axis xyz="0 0 1" />
    </joint>
    <joint name="joint2" type="revolute">
        <parent link="link1" />
        <child link="link2" />
        <origin rpy="0 0 1.5707963267948966" xyz="0 0.12249 0" />
        <limit effort="10000000" lower="-2.0" upper="2.0" velocity="46" />
        <axis xyz="0 0 1" />
    </joint>
    <joint name="joint3" type="revolute">
        <parent link="link2" />
        <child link="link3" />
        <origin rpy="-1.5707963267948966 0 0" xyz="0.1365 0 0" />
        <limit effort="10000000" lower="-1.57" upper="1.57" velocity="46" />
        <axis xyz="0 0 1" />
    </joint>
    <joint name="joint4" type="revolute">
        <parent link="link3" />
        <child link="link4" />
        <origin rpy="0 0 0" xyz="0.075511 0 0" />
        <limit effort="10000000" lower="-2.0" upper="2.0" velocity="46" />
        <axis xyz="0 0 1" />
    </joint>
    <joint name="joint5" type="revolute">
        <parent link="link4" />
        <child link="link5" />
        <origin rpy="0 0 0" xyz="0.072489 0 0" />
        <limit effort="10000000" lower="-2.3" upper="2.3" velocity="46" />
        <axis xyz="0 0 1" />
    </joint>
    <joint name="jointEndEffectorBase" type="fixed">
        <parent link="link5" />
        <child link="end_effector_base" />
        <origin rpy="0 0 0" xyz="0.04526 0 0" />
        <!--axis xyz="1 0 0" />
      <limit effort="0" velocity="0" lower="0" upper="0" /-->
    </joint>
    <transmission name="transmission_1">
        <type>transmission_interface/SimpleTransmission</type>
        <joint name="joint1">
            <hardwareInterface>hardware_interface/EffortJointInterface</hardwareInterface>
        </joint>
        <actuator name="motor_1">
            <hardwareInterface>hardware_interface/EffortActuatorInterface</hardwareInterface>
            <mechanicalReduction>1</mechanicalReduction>
        </actuator>
    </transmission>
    <transmission name="transmission_2">
        <type>transmission_interface/SimpleTransmission</type>
        <joint name="joint2">
            <hardwareInterface>hardware_interface/EffortJointInterface</hardwareInterface>
        </joint>
        <actuator name="motor_2">
            <hardwareInterface>hardware_interface/EffortActuatorInterface</hardwareInterface>
            <mechanicalReduction>1</mechanicalReduction>
        </actuator>
    </transmission>
    <transmission name="transmission_3">
        <type>transmission_interface/SimpleTransmission</type>
        <joint name="joint3">
            <hardwareInterface>hardware_interface/EffortJointInterface</hardwareInterface>
        </joint>
        <actuator name="motor_3">
            <hardwareInterface>hardware_interface/EffortActuatorInterface</hardwareInterface>
            <mechanicalReduction>1</mechanicalReduction>
        </actuator>
    </transmission>
    <transmission name="transmission_4">
        <type>transmission_interface/SimpleTransmission</type>
        <joint name="joint4">
            <hardwareInterface>hardware_interface/EffortJointInterface</hardwareInterface>
        </joint>
        <actuator name="motor_4">
            <hardwareInterface>hardware_interface/EffortActuatorInterface</hardwareInterface>
            <mechanicalReduction>1</mechanicalReduction>
        </actuator>
    </transmission>
    <transmission name="transmission_5">
        <type>transmission_interface/SimpleTransmission</type>
        <joint name="joint5">
            <hardwareInterface>hardware_interface/EffortJointInterface</hardwareInterface>
        </joint>
        <actuator name="motor_5">
            <hardwareInterface>hardware_interface/EffortActuatorInterface</hardwareInterface>
            <mechanicalReduction>1</mechanicalReduction>
        </actuator>
    </transmission>
    <gazebo>
        <plugin name="gazebo_ros_control">
            <robotNamespace>/</robotNamespace>
        </plugin>
    </gazebo>
</robot>

